<?xml version="1.0" ?>
<sdf version="1.4">
  <model name="iri_wam">
    <link name="wam_link0">
      <pose>0.220000 0.140000 0.346000 0.000000 0.000000 0.000000</pose>
      <inertial>
        <pose>0.000000 0.000000 0.000000 0.000000 0.000000 0.000000</pose>
        <mass>20.000000</mass>
        <inertia>
          <ixx>1.000000</ixx>
          <ixy>0.000000</ixy>
          <ixz>0.000000</ixz>
          <iyy>1.000000</iyy>
          <iyz>0.000000</iyz>
          <izz>1.000000</izz>
        </inertia>
      </inertial>
      <collision name="wam_link0_collision">
        <pose>0.000000 0.000000 0.000000 0.000000 0.000000 0.000000</pose>
        <geometry>
          <mesh>
            <scale>1.000000 1.000000 1.000000</scale>
            <uri>model://WAM Model/meshes/wambase.stl</uri>
          </mesh>
        </geometry>
        <surface>
          <contact>
            <ode />
          </contact>
          <friction>
            <ode />
          </friction>
        </surface>
      </collision>
      <visual name="wam_link0_vis">
        <pose>0.000000 0.000000 0.000000 0.000000 0.000000 0.000000</pose>
        <geometry>
          <mesh>
            <scale>1.000000 1.000000 1.000000</scale>
            <uri>model://WAM Model/meshes/wambase.stl</uri>
          </mesh>
        </geometry>
        <material />
      </visual>
      <gravity>1</gravity>
      <velocity_decay>
        <linear>0.000000</linear>
        <angular>0.000000</angular>
      </velocity_decay>
      <self_collide>1</self_collide>
    </link>
    <joint name="wam0_fix" type="revolute">
      <child>wam_link0</child>
      <parent>world</parent>
      <axis>
        <limit>
          <lower>0.000000</lower>
          <upper>0.000000</upper>
        </limit>
        <dynamics>
          <damping>0.000000</damping>
        </dynamics>
        <xyz>0.000000 0.000000 1.000000</xyz>
      </axis>
    </joint>
    <link name="wam_link1">
      <pose>0.220000 0.140000 0.346000 0.000000 0.000000 0.000000</pose>
      <inertial>
        <pose>0.000000 0.000000 0.000000 0.000000 0.000000 0.000000</pose>
        <mass>8.393600</mass>
        <inertia>
          <ixx>1.000000</ixx>
          <ixy>0.000000</ixy>
          <ixz>0.000000</ixz>
          <iyy>1.000000</iyy>
          <iyz>0.000000</iyz>
          <izz>1.000000</izz>
        </inertia>
      </inertial>
      <collision name="wam_link1_collision">
        <pose>0.000000 0.000000 0.000000 0.000000 0.000000 0.000000</pose>
        <geometry>
          <mesh>
            <scale>1.000000 1.000000 1.000000</scale>
            <uri>model://WAM Model/meshes/wam1.stl</uri>
          </mesh>
        </geometry>
        <surface>
          <contact>
            <ode />
          </contact>
          <friction>
            <ode />
          </friction>
        </surface>
      </collision>
      <visual name="wam_link1_vis">
        <pose>0.000000 0.000000 0.000000 0.000000 0.000000 0.000000</pose>
        <geometry>
          <mesh>
            <scale>1.000000 1.000000 1.000000</scale>
            <uri>model://WAM Model/meshes/wam1.stl</uri>
          </mesh>
        </geometry>
        <material />
      </visual>
      <gravity>1</gravity>
      <velocity_decay>
        <linear>0.000000</linear>
        <angular>0.000000</angular>
      </velocity_decay>
      <self_collide>1</self_collide>
    </link>
    <joint name="j1_joint" type="revolute">
      <child>wam_link1</child>
      <parent>wam_link0</parent>
      <axis>
        <xyz>0.000000 0.000000 1.000000</xyz>
        <limit>
          <lower>-2.600000</lower>
          <upper>2.600000</upper>
          <effort>30.000000</effort>
          <velocity>2.000000</velocity>
        </limit>
        <dynamics>
          <damping>1</damping>
	  <!--default value is 100 -->
        </dynamics>
      </axis>
    </joint>
    <link name="wam_link2">
      <pose>0.220000 0.140000 0.346000 0.000000 0.000000 0.000000</pose>
      <inertial>
        <pose>0.000000 0.000000 0.000000 0.000000 0.000000 0.000000</pose>
        <mass>4.848700</mass>
        <inertia>
          <ixx>1.000000</ixx>
          <ixy>0.000000</ixy>
          <ixz>0.000000</ixz>
          <iyy>0.100000</iyy>
          <iyz>0.000000</iyz>
          <izz>0.100000</izz>
        </inertia>
      </inertial>
      <collision name="wam_link2_collision">
        <pose>0.000000 0.000000 0.000000 0.000000 0.000000 0.000000</pose>
        <geometry>
          <mesh>
            <scale>1.000000 1.000000 1.000000</scale>
            <uri>model://WAM Model/meshes/wam2.stl</uri>
          </mesh>
        </geometry>
        <surface>
          <contact>
            <ode />
          </contact>
          <friction>
            <ode />
          </friction>
        </surface>
      </collision>
      <visual name="wam_link2_vis">
        <pose>0.000000 0.000000 0.000000 0.000000 0.000000 0.000000</pose>
        <geometry>
          <mesh>
            <scale>1.000000 1.000000 1.000000</scale>
            <uri>model://WAM Model/meshes/wam2.stl</uri>
          </mesh>
        </geometry>
        <material />
      </visual>
      <gravity>1</gravity>
      <velocity_decay>
        <linear>0.000000</linear>
        <angular>0.000000</angular>
      </velocity_decay>
      <self_collide>1</self_collide>
    </link>
    <joint name="j2_joint" type="revolute">
      <child>wam_link2</child>
      <parent>wam_link1</parent>
      <axis>
        <xyz>0.000000 1.000000 0.000000</xyz>
        <limit>
          <lower>-2.000000</lower>
          <upper>2.000000</upper>
          <effort>30.000000</effort>
          <velocity>2.000000</velocity>
        </limit>
        <dynamics>
          <damping>100.000000</damping>
        </dynamics>
      </axis>
    </joint>
    <link name="wam_link3">
      <pose>0.220000 0.140000 0.346000 0.000000 0.000000 0.000000</pose>
      <inertial>
        <pose>0.000000 0.000000 0.225000 0.000000 0.000000 0.000000</pose>
        <mass>1.725100</mass>
        <inertia>
          <ixx>1.000000</ixx>
          <ixy>0.000000</ixy>
          <ixz>0.000000</ixz>
          <iyy>0.100000</iyy>
          <iyz>0.000000</iyz>
          <izz>0.100000</izz>
        </inertia>
      </inertial>
      <collision name="wam_link3_collision">
        <pose>0.000000 0.000000 0.000000 0.000000 0.000000 0.000000</pose>
        <geometry>
          <mesh>
            <scale>1.000000 1.000000 1.000000</scale>
            <uri>model://WAM Model/meshes/wam3.stl</uri>
          </mesh>
        </geometry>
        <surface>
          <contact>
            <ode />
          </contact>
          <friction>
            <ode />
          </friction>
        </surface>
      </collision>
      <visual name="wam_link3_vis">
        <pose>0.000000 0.000000 0.000000 0.000000 0.000000 0.000000</pose>
        <geometry>
          <mesh>
            <scale>1.000000 1.000000 1.000000</scale>
            <uri>model://WAM Model/meshes/wam3.stl</uri>
          </mesh>
        </geometry>
        <material />
      </visual>
      <gravity>1</gravity>
      <velocity_decay>
        <linear>0.000000</linear>
        <angular>0.000000</angular>
      </velocity_decay>
      <self_collide>1</self_collide>
    </link>
    <joint name="j3_joint" type="revolute">
      <child>wam_link3</child>
      <parent>wam_link2</parent>
      <axis>
        <xyz>0.000000 0.000000 1.000000</xyz>
        <limit>
          <lower>-2.800000</lower>
          <upper>2.800000</upper>
          <effort>30.000000</effort>
          <velocity>2.000000</velocity>
        </limit>
        <dynamics>
          <damping>100.000000</damping>
        </dynamics>
      </axis>
    </joint>
    <link name="wam_link4">
      <pose>0.265000 0.140000 0.896000 -1.570800 0.000000 0.000000</pose>
      <inertial>
        <pose>-0.045000 -0.150000 0.000000 0.000000 0.000000 0.000000</pose>
        <mass>2.082400</mass>
        <inertia>
          <ixx>1.000000</ixx>
          <ixy>0.000000</ixy>
          <ixz>0.000000</ixz>
          <iyy>0.100000</iyy>
          <iyz>0.000000</iyz>
          <izz>0.100000</izz>
        </inertia>
      </inertial>
      <collision name="wam_link4_collision">
        <pose>0.000000 0.000000 0.000000 0.000000 0.000000 0.000000</pose>
        <geometry>
          <mesh>
            <scale>1.000000 1.000000 1.000000</scale>
            <uri>model://WAM Model/meshes/wam4.stl</uri>
          </mesh>
        </geometry>
        <surface>
          <contact>
            <ode />
          </contact>
          <friction>
            <ode />
          </friction>
        </surface>
      </collision>
      <visual name="wam_link4_vis">
        <pose>0.000000 0.000000 0.000000 0.000000 0.000000 0.000000</pose>
        <geometry>
          <mesh>
            <scale>1.000000 1.000000 1.000000</scale>
            <uri>model://WAM Model/meshes/wam4.stl</uri>
          </mesh>
        </geometry>
        <material />
      </visual>
      <gravity>1</gravity>
      <velocity_decay>
        <linear>0.000000</linear>
        <angular>0.000000</angular>
      </velocity_decay>
      <self_collide>1</self_collide>
    </link>
    <joint name="j4_joint" type="revolute">
      <child>wam_link4</child>
      <parent>wam_link3</parent>
      <axis>
        <xyz>0.000000 1.000000 0.000000</xyz>
        <limit>
          <lower>-0.900000</lower>
          <upper>2.800000</upper>
          <effort>35.000000</effort>
          <velocity>2.000000</velocity>
        </limit>
        <dynamics>
          <damping>100.000000</damping>
        </dynamics>
      </axis>
    </joint>
    <link name="wam_link5">
      <pose>0.220000 0.140000 1.196000 0.000000 0.000000 0.000000</pose>
      <inertial>
        <pose>0.000000 0.000000 0.000000 0.000000 0.000000 0.000000</pose>
        <mass>0.306700</mass>
        <inertia>
          <ixx>1.000000</ixx>
          <ixy>0.000000</ixy>
          <ixz>0.000000</ixz>
          <iyy>0.100000</iyy>
          <iyz>0.000000</iyz>
          <izz>0.100000</izz>
        </inertia>
      </inertial>
      <collision name="wam_link5_collision">
        <pose>0.000000 0.000000 0.000000 0.000000 0.000000 0.000000</pose>
        <geometry>
          <mesh>
            <scale>1.000000 1.000000 1.000000</scale>
            <uri>model://WAM Model/meshes/wam5.stl</uri>
          </mesh>
        </geometry>
        <surface>
          <contact>
            <ode />
          </contact>
          <friction>
            <ode />
          </friction>
        </surface>
      </collision>
      <visual name="wam_link5_vis">
        <pose>0.000000 0.000000 0.000000 0.000000 0.000000 0.000000</pose>
        <geometry>
          <mesh>
            <scale>1.000000 1.000000 1.000000</scale>
            <uri>model://WAM Model/meshes/wam5.stl</uri>
          </mesh>
        </geometry>
        <material />
      </visual>
      <gravity>1</gravity>
      <velocity_decay>
        <linear>0.000000</linear>
        <angular>0.000000</angular>
      </velocity_decay>
      <self_collide>1</self_collide>
    </link>
    <joint name="j5_joint" type="revolute">
      <child>wam_link5</child>
      <parent>wam_link4</parent>
      <axis>
        <xyz>0.000000 0.000000 1.000000</xyz>
        <limit>
          <lower>-4.800000</lower>
          <upper>1.300000</upper>
          <effort>30.000000</effort>
          <velocity>2.000000</velocity>
        </limit>
        <dynamics>
          <damping>100.000000</damping>
        </dynamics>
      </axis>
    </joint>
    <link name="wam_link6">
      <pose>0.220000 0.140000 1.196000 -1.570800 0.000000 0.000000</pose>
      <inertial>
        <pose>0.000000 0.000000 0.000000 0.000000 0.000000 0.000000</pose>
        <mass>0.427800</mass>
        <inertia>
          <ixx>1.000000</ixx>
          <ixy>0.000000</ixy>
          <ixz>0.000000</ixz>
          <iyy>0.100000</iyy>
          <iyz>0.000000</iyz>
          <izz>0.100000</izz>
        </inertia>
      </inertial>
      <collision name="wam_link6_collision">
        <pose>0.000000 0.000000 0.000000 0.000000 0.000000 0.000000</pose>
        <geometry>
          <mesh>
            <scale>1.000000 1.000000 1.000000</scale>
            <uri>model://WAM Model/meshes/wam6.stl</uri>
          </mesh>
        </geometry>
        <surface>
          <contact>
            <ode />
          </contact>
          <friction>
            <ode />
          </friction>
        </surface>
      </collision>
      <visual name="wam_link6_vis">
        <pose>0.000000 0.000000 0.000000 0.000000 0.000000 0.000000</pose>
        <geometry>
          <mesh>
            <scale>1.000000 1.000000 1.000000</scale>
            <uri>model://WAM Model/meshes/wam6.stl</uri>
          </mesh>
        </geometry>
        <material />
      </visual>
      <gravity>1</gravity>
      <velocity_decay>
        <linear>0.000000</linear>
        <angular>0.000000</angular>
      </velocity_decay>
      <self_collide>1</self_collide>
    </link>
    <joint name="j6_joint" type="revolute">
      <child>wam_link6</child>
      <parent>wam_link5</parent>
      <axis>
        <xyz>0.000000 1.000000 0.000000</xyz>
        <limit>
          <lower>-1.600000</lower>
          <upper>1.600000</upper>
          <effort>30.000000</effort>
          <velocity>2.000000</velocity>
        </limit>
        <dynamics>
          <damping>100.000000</damping>
        </dynamics>
      </axis>
    </joint>
    <link name="wam_link7">
      <pose>0.220000 0.140000 1.196000 0.000000 0.000000 0.000000</pose>
      <inertial>
        <pose>0.000000 0.000000 0.000000 0.000000 0.000000 0.000000</pose>
        <mass>0.055700</mass>
        <inertia>
          <ixx>1.000000</ixx>
          <ixy>0.000000</ixy>
          <ixz>0.000000</ixz>
          <iyy>0.100000</iyy>
          <iyz>0.000000</iyz>
          <izz>0.100000</izz>
        </inertia>
      </inertial>
      <collision name="wam_link7_collision">
        <pose>0.000000 0.000000 0.000000 0.000000 0.000000 0.000000</pose>
        <geometry>
          <mesh>
            <scale>1.000000 1.000000 1.000000</scale>
            <uri>model://WAM Model/meshes/wam7.stl</uri>
          </mesh>
        </geometry>
        <surface>
          <contact>
            <ode />
          </contact>
          <friction>
            <ode />
          </friction>
        </surface>
      </collision>
      <visual name="wam_link7_vis">
        <pose>0.000000 0.000000 0.000000 0.000000 0.000000 0.000000</pose>
        <geometry>
          <mesh>
            <scale>1.000000 1.000000 1.000000</scale>
            <uri>model://WAM Model/meshes/wam7.stl</uri>
          </mesh>
        </geometry>
        <material />
      </visual>
      <gravity>1</gravity>
      <velocity_decay>
        <linear>0.000000</linear>
        <angular>0.000000</angular>
      </velocity_decay>
      <self_collide>1</self_collide>
    </link>
    <joint name="j7_joint" type="revolute">
      <child>wam_link7</child>
      <parent>wam_link6</parent>
      <axis>
        <xyz>0.000000 0.000000 1.000000</xyz>
        <limit>
          <lower>-2.200000</lower>
          <upper>2.200000</upper>
          <effort>30.000000</effort>
          <velocity>2.000000</velocity>
        </limit>
        <dynamics>
          <damping>100.000000</damping>
        </dynamics>
      </axis>
    </joint>
    <plugin name="ros_wam_plugin" filename="build/libros_wam_plugin.so" />
  </model>
</sdf>
